<!-- Bulldozer model

This model implements a Bulldozer with functioning velocity actuation and
textured meshes.

Copyright, 2023, Vilella Kenny.
-->

<mujoco model="bulldozer">
  <compiler meshdir="mesh" texturedir="texture"/>

  <option timestep="0.001"/>

  <extension>
    <plugin plugin="mujoco.soil">
      <instance name="terrain">
        <config key="cell_size_z" value="0.05"/>
        <config key="repose_angle" value="0.85"/>
        <config key="max_iterations" value="10"/>
        <config key="cell_buffer" value="4"/>
        <config key="amp_noise" value="0.0"/>
      </instance>
    </plugin>
  </extension>

  <default>
    <velocity ctrllimited="true" ctrlrange="-0.5 0.5"/>
    <mesh scale="1 1 1"/>
    <material emission="0.25" rgba="1 1 1 1"/>
    <default class="wheel">
      <geom type="cylinder" mass ="100000" size=".18 .3" group="1"
            condim="6" friction="0.5 0.002 0.001" priority="1"/>
    </default>
    <default class="wheelslide">
      <joint type="slide" axis="0 1 0" damping="0.3" limited="true" ref="0.0" range="-0.2 0.2" pos="0 0 0"/>
    </default>
  </default>

  <visual>
    <headlight ambient="1 1 1" diffuse="0 0 0" specular="0 0 0"/>
  </visual>

  <asset>
    <hfield name="terrain" nrow="320" ncol="320" size="16.0 16.0 12.0 4.0"/>
    <hfield name="blade soil" nrow="320" ncol="320" size="16.0 16.0 12.0 0.01"/>

    <texture name="floor" type="2d" file="floor_texture.png"/>
    <material name="floor" emission="1" texrepeat="10 10" texture="floor"/>

    <mesh file="caterpillar.obj"/>
    <texture name="caterpillar" type="2d" file="caterpillar_texture.png"/>
    <material name="caterpillar" emission="1" texture="caterpillar"/>

    <mesh file="chassis.obj"/>
    <texture name="chassis" type="2d" file="chassis_texture.png"/>
    <material name="chassis" emission="1" texture="chassis"/>

    <mesh file="chassis_blade_piston_rod.obj"/>
    <texture name="chassis_blade_piston_rod" type="2d" file="chassis_blade_piston_rod_texture.png"/>
    <material name="chassis_blade_piston_rod" emission="1" texture="chassis_blade_piston_rod"/>

    <mesh file="blade.obj"/>
    <texture name="blade" type="2d" file="blade_texture.png"/>
    <material name="blade" emission="1" texture="blade"/>

    <mesh file="caterpillar_arm.obj"/>
    <texture name="caterpillar_arm" type="2d" file="caterpillar_arm_texture.png"/>
    <material name="caterpillar_arm" emission="1" texture="caterpillar_arm"/>

    <mesh file="caterpillar_blade_piston_tube.obj"/>
    <texture name="caterpillar_blade_piston_tube" type="2d" file="caterpillar_blade_piston_tube_texture.png"/>
    <material name="caterpillar_blade_piston_tube" emission="1" texture="caterpillar_blade_piston_tube"/>

    <mesh file="caterpillar_blade_piston_rod.obj"/>
    <texture name="caterpillar_blade_piston_rod" type="2d" file="caterpillar_blade_piston_rod_texture.png"/>
    <material name="caterpillar_blade_piston_rod" emission="1" texture="caterpillar_blade_piston_rod"/>
  </asset>

  <worldbody>
    <!-- Floor -->
    <body name="floor" pos="0 0 0" euler="0 0 0">
      <geom name="terrain" type="hfield" hfield="terrain" material="floor"/>
    </body> <!-- Floor -->

    <!-- Blade soil layer -->
    <body name="soil" pos="0 0 0" euler="0 0 0">
      <geom name="blade soil" type="hfield" hfield="blade soil"
          material="floor" contype="0" conaffinity="0"/>
    </body> <!-- Blade soil layer -->

    <!-- Caterpillar -->
    <body name="caterpillar" pos="0 0 1.10" euler="0 0 0">
      <joint type="free" limited='false' damping="0" stiffness="1" armature="0"/>
      <geom name="caterpillar" type="mesh" mesh="caterpillar"
            material="caterpillar" pos="0 0 0" euler="0 0 0"/>
      <inertial pos="-0.406 0 0.890" mass="12000"
                fullinertia="25000 28500 44000 -7 3300 4"/>

      <!-- Caterpillar arm -->
      <body name="caterpillar_arm" pos="-1.09 0 0.815" euler="0 4.754 0">
        <joint name="caterpillar_arm" type="hinge" axis="0 1 0" pos="0 0 0"/>
        <geom name="caterpillar_arm" type="mesh" mesh="caterpillar_arm"
              material="caterpillar_arm" pos="0 0 0" euler="0 0 0"/>
        <inertial pos="2.179 0 0.047" mass="4000" diaginertia="80 6200 6200"/>

        <!-- Caterpillar/Blade piston tube -->
        <body name="caterpillar_blade_piston_tube" pos="2.700 0 0.322" euler="0 -26.387 0">
          <joint name="caterpillar_blade_piston_tube" type="hinge" axis="0 1 0" pos="0 0 0"/>
          <geom name="caterpillar_blade_piston_tube" type="mesh" mesh="caterpillar_blade_piston_tube"
                material="caterpillar_blade_piston_tube" pos="0 0 0" euler="0 0 0"/>
          <inertial pos="0.942 0 0" mass="400" diaginertia="2.9 67 67"/>

          <!-- Caterpillar/Blade piston rod -->
          <body name="caterpillar_blade_piston_rod" pos="1.032 0 0" euler="0 0 0">
            <joint name="caterpillar_blade_piston_rod" type="slide" axis="1 0 0" limited="true"
                   ref="1.032" range="0.9 1.35" pos="0 0 0"/>
            <geom name="caterpillar_blade_piston_rod" type="mesh" mesh="caterpillar_blade_piston_rod"
                  material="caterpillar_blade_piston_rod" pos="0 0 0" euler="0 0 0"/>
            <inertial pos="0.476 0 0" mass="200" diaginertia="0.4 11 11"/>
          </body> <!-- Caterpillar/Blade piston rod -->
        </body> <!-- Caterpillar/Blade piston tube -->
      </body> <!-- Caterpillar arm-->

      <!-- Chassis -->
      <body name="chassis" pos="0 0 0.722" euler="0 0 0">
        <geom name="chassis" type="mesh" mesh="chassis" material="chassis"
              pos="0 0 0" euler="0 0 0"/>
        <inertial pos="-0.257 0.024 1.640" mass="38000"
                  fullinertia="70000 110000 100000 100 7000 -2000"/>

        <!-- Chassis/Blade piston rod -->
        <body name="chassis_blade_piston_rod" pos="2.544 0 1.301" euler="0 70.559 0">
          <joint name="chassis_blade_piston_rod" type="slide" axis="1 0 0" limited="true"
                 ref="2.544" range="1.144 2.544" pos="0 0 0"/>
          <geom name="chassis_blade_piston_rod" type="mesh" mesh="chassis_blade_piston_rod"
                material="chassis_blade_piston_rod" pos="0 0 0" euler="0 0 0"/>
          <inertial pos="1.033 0 0" mass="250" diaginertia="0.4 50 50"/>

          <!-- Blade -->
          <body name="blade" pos="1.649 0 0" euler="0 -70.559 0">
            <joint name="blade" type="hinge" axis="0 1 0" pos="0 0 0"/>
            <geom name="blade" type="mesh" mesh="blade"
                  material="blade" pos="0 0 0" euler="0 0 0"/>
            <inertial pos="0.669 0 0.417" mass="13000"
                      fullinertia="35000 7500 32000 -0.08 1500 0.1"/>
          </body> <!-- Blade -->
        </body> <!-- Chassis/Blade piston rod -->
      </body> <!-- Chassis -->

      <body name="left wheel 1" pos="-2.0 1.3 0.15" zaxis="0 1 0">
        <joint class="wheelslide"/>
        <joint name="left 1"/>
        <geom class="wheel"/>
      </body>
        <body name="left wheel 2" pos="-1.6 1.3 0.15" zaxis="0 1 0">
          <joint class="wheelslide"/>
          <joint name="left 2"/>
          <geom class="wheel"/>
        </body>
        <body name="left wheel 3" pos="-1.2 1.3 0.15" zaxis="0 1 0">
          <joint class="wheelslide"/>
          <joint name="left 3"/>
          <geom class="wheel"/>
        </body>
        <body name="left wheel 4" pos="-0.8 1.3 0.15" zaxis="0 1 0">
          <joint class="wheelslide"/>
          <joint name="left 4"/>
          <geom class="wheel"/>
        </body>
        <body name="left wheel 5" pos="-0.4 1.3 0.15" zaxis="0 1 0">
          <joint class="wheelslide"/>
          <joint name="left 5"/>
          <geom class="wheel"/>
        </body>
        <body name="left wheel 6" pos="0.0 1.3 0.15" zaxis="0 1 0">
          <joint class="wheelslide"/>
          <joint name="left 6"/>
          <geom class="wheel"/>
        </body>
        <body name="left wheel 7" pos="0.4 1.3 0.15" zaxis="0 1 0">
          <joint class="wheelslide"/>
          <joint name="left 7"/>
          <geom class="wheel"/>
        </body>
        <body name="left wheel 8" pos="0.8 1.3 0.15" zaxis="0 1 0">
          <joint class="wheelslide"/>
          <joint name="left 8"/>
          <geom class="wheel"/>
        </body>
        <body name="left wheel 9" pos="1.2 1.3 0.15" zaxis="0 1 0">
          <joint class="wheelslide"/>
          <joint name="left 9"/>
          <geom class="wheel"/>
        </body>
        <body name="left wheel 10" pos="1.6 1.3 0.15" zaxis="0 1 0">
          <joint class="wheelslide"/>
          <joint name="left 10"/>
          <geom name="left wheel 10" class="wheel"/>
        </body>
        <body name="left wheel 11" pos="2.0 1.3 0.15" zaxis="0 1 0">
          <joint class="wheelslide"/>
          <joint name="left 11"/>
          <geom name="left wheel 11" class="wheel"/>
        </body>
        <body name="left wheel 12" pos="-2.4 1.3 0.15" zaxis="0 1 0">
          <joint class="wheelslide"/>
          <joint name="left 12"/>
          <geom class="wheel"/>
        </body>
        <body name="right wheel 1" pos="-2.0 -1.3 0.15" zaxis="0 1 0">
          <joint class="wheelslide"/>
          <joint name="right 1"/>
          <geom class="wheel"/>
        </body>
        <body name="right wheel 2" pos="-1.6 -1.3 0.15" zaxis="0 1 0">
          <joint class="wheelslide"/>
          <joint name="right 2"/>
          <geom class="wheel"/>
        </body>
        <body name="right wheel 3" pos="-1.2 -1.3 0.15" zaxis="0 1 0">
          <joint class="wheelslide"/>
          <joint name="right 3"/>
          <geom class="wheel"/>
        </body>
        <body name="right wheel 4" pos="-0.8 -1.3 0.15" zaxis="0 1 0">
          <joint class="wheelslide"/>
          <joint name="right 4"/>
          <geom class="wheel"/>
        </body>
        <body name="right wheel 5" pos="-0.4 -1.3 0.15" zaxis="0 1 0">
          <joint class="wheelslide"/>
          <joint name="right 5"/>
          <geom class="wheel"/>
        </body>
        <body name="right wheel 6" pos="0.0 -1.3 0.15" zaxis="0 1 0">
          <joint class="wheelslide"/>
          <joint name="right 6"/>
          <geom class="wheel"/>
        </body>
        <body name="right wheel 7" pos="0.4 -1.3 0.15" zaxis="0 1 0">
          <joint class="wheelslide"/>
          <joint name="right 7"/>
          <geom class="wheel"/>
        </body>
        <body name="right wheel 8" pos="0.8 -1.3 0.15" zaxis="0 1 0">
          <joint class="wheelslide"/>
          <joint name="right 8"/>
          <geom class="wheel"/>
        </body>
        <body name="right wheel 9" pos="1.2 -1.3 0.15" zaxis="0 1 0">
          <joint class="wheelslide"/>
          <joint name="right 9"/>
          <geom class="wheel"/>
        </body>
        <body name="right wheel 10" pos="1.6 -1.3 0.15" zaxis="0 1 0">
          <joint class="wheelslide"/>
          <joint name="right 10"/>
          <geom class="wheel"/>
        </body>
        <body name="right wheel 11" pos="2.0 -1.3 0.15" zaxis="0 1 0">
          <joint class="wheelslide"/>
          <joint name="right 11"/>
          <geom class="wheel"/>
        </body>
        <body name="right wheel 12" pos="-2.4 -1.3 0.15" zaxis="0 1 0">
          <joint class="wheelslide"/>
          <joint name="right 12"/>
          <geom class="wheel"/>
        </body>
    </body> <!-- Caterpillar -->
  </worldbody>

  <tendon>
    <fixed name="left crawler">
      <joint joint="left 1" coef="1000"/>
      <joint joint="left 2" coef="1000"/>
      <joint joint="left 3" coef="1000"/>
      <joint joint="left 4" coef="1000"/>
      <joint joint="left 5" coef="1000"/>
      <joint joint="left 6" coef="1000"/>
      <joint joint="left 7" coef="1000"/>
      <joint joint="left 8" coef="1000"/>
      <joint joint="left 9" coef="1000"/>
      <joint joint="left 10" coef="1000"/>
      <joint joint="left 11" coef="1000"/>
      <joint joint="left 12" coef="1000"/>
    </fixed>
    <fixed name="right crawler">
      <joint joint="right 1" coef="1000"/>
      <joint joint="right 2" coef="1000"/>
      <joint joint="right 3" coef="1000"/>
      <joint joint="right 4" coef="1000"/>
      <joint joint="right 5" coef="1000"/>
      <joint joint="right 6" coef="1000"/>
      <joint joint="right 7" coef="1000"/>
      <joint joint="right 8" coef="1000"/>
      <joint joint="right 9" coef="1000"/>
      <joint joint="right 10" coef="1000"/>
      <joint joint="right 11" coef="1000"/>
      <joint joint="right 12" coef="1000"/>
    </fixed>
  </tendon>

  <equality>
    <connect body1="caterpillar_arm" body2="blade" anchor="4.361 0 0"/>
    <connect body1="caterpillar_blade_piston_rod" body2="blade" anchor="0.644 0 0"/>
  </equality>

  <!-- Because the hydraulic pistons and caterpillar arm are merged, the
  collision algorithm seems to consider that they are colliding with other
  bodies. It is thus necessary to remove collision.-->
  <contact>
    <exclude body1="caterpillar_arm" body2="chassis_blade_piston_rod"/>
    <exclude body1="caterpillar_arm" body2="blade"/>
    <exclude body1="caterpillar_blade_piston_tube" body2="caterpillar"/>
    <exclude body1="caterpillar_blade_piston_tube" body2="chassis"/>
    <exclude body1="caterpillar_blade_piston_tube" body2="chassis_blade_piston_rod"/>
    <exclude body1="caterpillar_blade_piston_tube" body2="blade"/>
    <exclude body1="caterpillar_blade_piston_rod" body2="chassis_blade_piston_rod"/>
    <exclude body1="caterpillar_blade_piston_rod" body2="blade"/>
    <exclude body1="blade" body2="floor"/>
    <exclude body1="blade" body2="soil"/>
    <exclude body1="left wheel 1" body2="caterpillar"/>
    <exclude body1="left wheel 2" body2="caterpillar"/>
    <exclude body1="left wheel 3" body2="caterpillar"/>
    <exclude body1="left wheel 4" body2="caterpillar"/>
    <exclude body1="left wheel 5" body2="caterpillar"/>
    <exclude body1="left wheel 6" body2="caterpillar"/>
    <exclude body1="left wheel 7" body2="caterpillar"/>
    <exclude body1="left wheel 8" body2="caterpillar"/>
    <exclude body1="left wheel 9" body2="caterpillar"/>
    <exclude body1="left wheel 10" body2="caterpillar"/>
    <exclude body1="left wheel 11" body2="caterpillar"/>
    <exclude body1="left wheel 12" body2="caterpillar"/>
    <exclude body1="right wheel 1" body2="caterpillar"/>
    <exclude body1="right wheel 2" body2="caterpillar"/>
    <exclude body1="right wheel 3" body2="caterpillar"/>
    <exclude body1="right wheel 4" body2="caterpillar"/>
    <exclude body1="right wheel 5" body2="caterpillar"/>
    <exclude body1="right wheel 6" body2="caterpillar"/>
    <exclude body1="right wheel 7" body2="caterpillar"/>
    <exclude body1="right wheel 8" body2="caterpillar"/>
    <exclude body1="right wheel 9" body2="caterpillar"/>
    <exclude body1="right wheel 10" body2="caterpillar"/>
    <exclude body1="right wheel 11" body2="caterpillar"/>
    <exclude body1="right wheel 12" body2="caterpillar"/>
  </contact>

  <actuator>
    <velocity name="Blade inclination" joint="caterpillar_blade_piston_rod" kv="800000"/>
    <motor name="left crawler" tendon="left crawler" gear="100" ctrlrange="-1 1"/>
    <motor name="right crawler" tendon="right crawler" gear="100" ctrlrange="-1 1"/>
  </actuator>
</mujoco>
